<?xml version="1.0" ?>
<mujoco model="elrobot_follower_empty">
  <!-- norma-sim: generated by gen.py
     source_hash=sha256:0830c579e58bca05c1b3233567909b70ec4acf2deeb8b4907714baa95b859d79
     generator_version=1.0 -->
  
  
  <compiler angle="radian" meshdir="../assets" autolimits="true" discardvisual="false"/>
  

  
  <asset>
    
    
    <mesh name="base_link" content_type="model/stl" file="base_link.stl" scale="0.001 0.001 0.001"/>
    
    
    <mesh name="ST3215_1_v1_1" content_type="model/stl" file="ST3215_1_v1_1.stl" scale="0.001 0.001 0.001"/>
    
    
    <mesh name="Joint_01_1" content_type="model/stl" file="Joint_01_1.stl" scale="0.001 0.001 0.001"/>
    
    
    <mesh name="ST3215_2_v1_1" content_type="model/stl" file="ST3215_2_v1_1.stl" scale="0.001 0.001 0.001"/>
    
    
    <mesh name="Joint_02_1" content_type="model/stl" file="Joint_02_1.stl" scale="0.001 0.001 0.001"/>
    
    
    <mesh name="ST3215_3_v1_1" content_type="model/stl" file="ST3215_3_v1_1.stl" scale="0.001 0.001 0.001"/>
    
    
    <mesh name="Joint_03_v1_1" content_type="model/stl" file="Joint_03_v1_1.stl" scale="0.001 0.001 0.001"/>
    
    
    <mesh name="ST3215_4_v1_1" content_type="model/stl" file="ST3215_4_v1_1.stl" scale="0.001 0.001 0.001"/>
    
    
    <mesh name="Joint_04_v1_1" content_type="model/stl" file="Joint_04_v1_1.stl" scale="0.001 0.001 0.001"/>
    
    
    <mesh name="ST3215_5_v1_1" content_type="model/stl" file="ST3215_5_v1_1.stl" scale="0.001 0.001 0.001"/>
    
    
    <mesh name="Joint_05_v1_1" content_type="model/stl" file="Joint_05_v1_1.stl" scale="0.001 0.001 0.001"/>
    
    
    <mesh name="ST3215_6_v1_1" content_type="model/stl" file="ST3215_6_v1_1.stl" scale="0.001 0.001 0.001"/>
    
    
    <mesh name="Joint_06_v1_1" content_type="model/stl" file="Joint_06_v1_1.stl" scale="0.001 0.001 0.001"/>
    
    
    <mesh name="ST3215_7_v1_1" content_type="model/stl" file="ST3215_7_v1_1.stl" scale="0.001 0.001 0.001"/>
    
    
    <mesh name="Gripper_Base_v1_1" content_type="model/stl" file="Gripper_Base_v1_1.stl" scale="0.001 0.001 0.001"/>
    
    
    <mesh name="ST3215_8_v1_1" content_type="model/stl" file="ST3215_8_v1_1.stl" scale="0.001 0.001 0.001"/>
    
    
    <mesh name="Gripper_Gear_v1_1" content_type="model/stl" file="Gripper_Gear_v1_1.stl" scale="0.001 0.001 0.001"/>
    
    
    <mesh name="Gripper_Jaw_02_v1_1" content_type="model/stl" file="Gripper_Jaw_02_v1_1.stl" scale="0.001 0.001 0.001"/>
    
    
    <mesh name="Gripper_Jaw_01_v1_1" content_type="model/stl" file="Gripper_Jaw_01_v1_1.stl" scale="0.001 0.001 0.001"/>
    
  
    <texture name="grid" type="2d" builtin="checker" rgb1=".1 .2 .3" rgb2=".2 .3 .4" width="512" height="512" mark="cross" markrgb=".8 .8 .8"/>
    <material name="grid" texture="grid" texrepeat="1 1" texuniform="true" reflectance=".2"/>
  </asset>
  

  
  <worldbody>
    
    
    <geom type="mesh" contype="0" conaffinity="0" group="1" density="0" rgba="0.7 0.7 0.7 1" mesh="base_link"/>
    
    
    <geom type="mesh" rgba="0.7 0.7 0.7 1" mesh="base_link"/>
    
    
    <geom type="mesh" contype="0" conaffinity="0" group="1" density="0" rgba="0 0 0 1" mesh="ST3215_1_v1_1"/>
    
    
    <geom type="mesh" rgba="0 0 0 1" mesh="ST3215_1_v1_1"/>
    
    
    <body name="Joint_01_1" pos="0 0.042489 0.049005">
      
      
      <joint name="rev_motor_01" pos="0 0 0" axis="0 -0.008727 0.999962" range="-1.5509 1.5509" actuatorfrcrange="-2.94 2.94"/>
      
      
      <geom pos="0 -0.042489 -0.049005" quat="1 0 0 0" type="mesh" contype="0" conaffinity="0" group="1" density="0" rgba="0.7 0.7 0.7 1" mesh="Joint_01_1"/>
      
      
      <geom pos="0 -0.042489 -0.049005" quat="1 0 0 0" type="mesh" rgba="0.7 0.7 0.7 1" mesh="Joint_01_1"/>
      
      
      <geom pos="0 -0.042489 -0.049005" quat="1 0 0 0" type="mesh" contype="0" conaffinity="0" group="1" density="0" rgba="0 0 0 1" mesh="ST3215_2_v1_1"/>
      
      
      <geom pos="0 -0.042489 -0.049005" quat="1 0 0 0" type="mesh" rgba="0 0 0 1" mesh="ST3215_2_v1_1"/>
      
      
      <body name="Joint_02_1" pos="-0.019668 -0.000366 0.041933">
        
        
        <joint name="rev_motor_02" pos="0 0 0" axis="-0.999962 -7.6e-05 0.008726" range="-1.6122 1.6122" actuatorfrcrange="-2.94 2.94"/>
        
        
        <geom pos="0.019668 -0.042123 -0.090938" quat="1 0 0 0" type="mesh" contype="0" conaffinity="0" group="1" density="0" rgba="0.7 0.7 0.7 1" mesh="Joint_02_1"/>
        
        
        <geom pos="0.019668 -0.042123 -0.090938" quat="1 0 0 0" type="mesh" rgba="0.7 0.7 0.7 1" mesh="Joint_02_1"/>
        
        
        <geom pos="0.019668 -0.042123 -0.090938" quat="1 0 0 0" type="mesh" contype="0" conaffinity="0" group="1" density="0" rgba="0 0 0 1" mesh="ST3215_3_v1_1"/>
        
        
        <geom pos="0.019668 -0.042123 -0.090938" quat="1 0 0 0" type="mesh" rgba="0 0 0 1" mesh="ST3215_3_v1_1"/>
        
        
        <body name="Joint_03_v1_1" pos="-0.000122 -0.000796 0.091235">
          
          
          <joint name="rev_motor_03" pos="0 0 0" axis="-0.999848 -0.000152 0.017452" range="-1.761 1.761" actuatorfrcrange="-2.94 2.94"/>
          
          
          <geom pos="0.01979 -0.041327 -0.182173" quat="1 0 0 0" type="mesh" contype="0" conaffinity="0" group="1" density="0" rgba="0.7 0.7 0.7 1" mesh="Joint_03_v1_1"/>
          
          
          <geom pos="0.01979 -0.041327 -0.182173" quat="1 0 0 0" type="mesh" rgba="0.7 0.7 0.7 1" mesh="Joint_03_v1_1"/>
          
          
          <geom pos="0.01979 -0.041327 -0.182173" quat="1 0 0 0" type="mesh" contype="0" conaffinity="0" group="1" density="0" rgba="0 0 0 1" mesh="ST3215_4_v1_1"/>
          
          
          <geom pos="0.01979 -0.041327 -0.182173" quat="1 0 0 0" type="mesh" rgba="0 0 0 1" mesh="ST3215_4_v1_1"/>
          
          
          <body name="Joint_04_v1_1" pos="0.000973 0.037162 0.037065">
            
            
            <joint name="rev_motor_04" pos="0 0 0" axis="-0.99981 0.008574 0.017527" range="-1.7533 1.7533" actuatorfrcrange="-2.94 2.94"/>
            
            
            <geom pos="0.018817 -0.078489 -0.219238" quat="1 0 0 0" type="mesh" contype="0" conaffinity="0" group="1" density="0" rgba="0.7 0.7 0.7 1" mesh="Joint_04_v1_1"/>
            
            
            <geom pos="0.018817 -0.078489 -0.219238" quat="1 0 0 0" type="mesh" rgba="0.7 0.7 0.7 1" mesh="Joint_04_v1_1"/>
            
            
            <geom pos="0.018817 -0.078489 -0.219238" type="mesh" contype="0" conaffinity="0" group="1" density="0" rgba="0 0 0 1" mesh="ST3215_5_v1_1"/>
            
            
            <geom pos="0.018817 -0.078489 -0.219238" type="mesh" rgba="0 0 0 1" mesh="ST3215_5_v1_1"/>
            
            
            <body name="Joint_05_v1_1" pos="0.020714 0.082863 1.6e-05">
              
              
              <joint name="rev_motor_05" pos="0 0 0" axis="-0.008573 -0.999963 0.000151" range="-3.1907 2.6998" actuatorfrcrange="-2.94 2.94"/>
              
              
              <geom pos="-0.001897 -0.161352 -0.219254" quat="1 0 0 0" type="mesh" contype="0" conaffinity="0" group="1" density="0" rgba="0.7 0.7 0.7 1" mesh="Joint_05_v1_1"/>
              
              
              <geom pos="-0.001897 -0.161352 -0.219254" quat="1 0 0 0" type="mesh" rgba="0.7 0.7 0.7 1" mesh="Joint_05_v1_1"/>
              
              
              <geom pos="-0.001897 -0.161352 -0.219254" quat="1 0 0 0" type="mesh" contype="0" conaffinity="0" group="1" density="0" rgba="0 0 0 1" mesh="ST3215_6_v1_1"/>
              
              
              <geom pos="-0.001897 -0.161352 -0.219254" quat="1 0 0 0" type="mesh" rgba="0 0 0 1" mesh="ST3215_6_v1_1"/>
              
              
              <body name="Joint_06_v1_1" pos="-0.019923 0.042907 0.00035">
                
                
                <joint name="rev_motor_06" pos="0 0 0" axis="-0.999697 0.0173 0.017525" range="-1.3775 1.7641" actuatorfrcrange="-2.94 2.94"/>
                
                
                <geom pos="0.018026 -0.204259 -0.219604" quat="1 0 0 0" type="mesh" contype="0" conaffinity="0" group="1" density="0" rgba="0.7 0.7 0.7 1" mesh="Joint_06_v1_1"/>
                
                
                <geom pos="0.018026 -0.204259 -0.219604" quat="1 0 0 0" type="mesh" rgba="0.7 0.7 0.7 1" mesh="Joint_06_v1_1"/>
                
                
                <geom pos="0.018026 -0.204259 -0.219604" type="mesh" contype="0" conaffinity="0" group="1" density="0" rgba="0 0 0 1" mesh="ST3215_7_v1_1"/>
                
                
                <geom pos="0.018026 -0.204259 -0.219604" type="mesh" rgba="0 0 0 1" mesh="ST3215_7_v1_1"/>
                
                
                <body name="Gripper_Base_v1_1" pos="0.020951 0.055307 -0.000712">
                  
                  
                  <joint name="rev_motor_07" pos="0 0 0" axis="-0.017144 -0.999812 0.009029" range="-3.071 2.7796" actuatorfrcrange="-2.94 2.94"/>
                  
                  
                  <geom pos="-0.002925 -0.259566 -0.218892" quat="1 0 0 0" type="mesh" contype="0" conaffinity="0" group="1" density="0" rgba="0.7 0.7 0.7 1" mesh="Gripper_Base_v1_1"/>
                  
                  
                  <geom pos="-0.002925 -0.259566 -0.218892" quat="1 0 0 0" type="mesh" rgba="0.7 0.7 0.7 1" mesh="Gripper_Base_v1_1"/>
                  
                  
                  <geom pos="-0.002925 -0.259566 -0.218892" type="mesh" contype="0" conaffinity="0" group="1" density="0" rgba="0 0 0 1" mesh="ST3215_8_v1_1"/>
                  
                  
                  <geom pos="-0.002925 -0.259566 -0.218892" type="mesh" rgba="0 0 0 1" mesh="ST3215_8_v1_1"/>
                  
                  
                  <body name="Gripper_Gear_v1_1" pos="0.000776 0.045242 -0.000409">
                    
                    
                    <joint name="rev_motor_08" pos="0 0 0" axis="0.017144 0.999812 -0.009029" range="0 2.2028" actuatorfrcrange="-2.94 2.94"/>
                    
                    
                    <geom pos="-0.003701 -0.304808 -0.218483" quat="1 0 0 0" type="mesh" contype="0" conaffinity="0" group="1" density="0" rgba="0.7 0.7 0.7 1" mesh="Gripper_Gear_v1_1"/>
                    
                    
                    <geom pos="-0.003701 -0.304808 -0.218483" quat="1 0 0 0" type="mesh" rgba="0.7 0.7 0.7 1" mesh="Gripper_Gear_v1_1"/>
                    
                  
                  </body>
                  
                  
                  <body name="Gripper_Jaw_02_v1_1" pos="0.311734 -0.199648 0.032849">
                    
                    
                    <joint name="rev_motor_08_1" pos="0 0 0" axis="-0.999697 0.0173 0.017525" type="slide" range="-0.0255 0" actuatorfrcrange="-2.94 2.94"/>
                    
                    
                    <geom pos="-0.314659 -0.059918 -0.251741" type="mesh" contype="0" conaffinity="0" group="1" density="0" rgba="0.7 0.7 0.7 1" mesh="Gripper_Jaw_02_v1_1"/>
                    
                    
                    <geom pos="-0.314659 -0.059918 -0.251741" type="mesh" rgba="0.7 0.7 0.7 1" mesh="Gripper_Jaw_02_v1_1"/>
                    
                  
                  </body>
                  
                  
                  <body name="Gripper_Jaw_01_v1_1" pos="0.308573 -0.243367 -0.049391">
                    
                    
                    <joint name="rev_motor_08_2" pos="0 0 0" axis="-0.999697 0.0173 0.017525" type="slide" range="0 0.0255" actuatorfrcrange="-2.94 2.94"/>
                    
                    
                    <geom pos="-0.311498 -0.016199 -0.171401" type="mesh" contype="0" conaffinity="0" group="1" density="0" rgba="0.7 0.7 0.7 1" mesh="Gripper_Jaw_01_v1_1"/>
                    
                    
                    <geom pos="-0.311498 -0.016199 -0.171401" type="mesh" rgba="0.7 0.7 0.7 1" mesh="Gripper_Jaw_01_v1_1"/>
                    
                  
                  </body>
                  
                
                </body>
                
              
              </body>
              
            
            </body>
            
          
          </body>
          
        
        </body>
        
      
      </body>
      
    
    </body>
    
  
    <light name="default_top" pos="0 0 3" dir="0 0 -1"/>
    <geom name="floor" type="plane" size="2 2 0.1" material="grid"/>
  </worldbody>
  

  <option timestep="0.002" iterations="50" solver="Newton" gravity="0 0 -9.81" integrator="RK4"/>
  <equality>
    <tendon tendon1="mimic_rev_motor_08_1" solref="0.002 1" solimp="0.99 0.999 0.0001 0.5 2"/>
    <tendon tendon1="mimic_rev_motor_08_2" solref="0.002 1" solimp="0.99 0.999 0.0001 0.5 2"/>
  </equality>
  <tendon>
    <fixed name="mimic_rev_motor_08_1">
      <joint joint="rev_motor_08_1" coef="1"/>
      <joint joint="rev_motor_08" coef="0.0115"/>
    </fixed>
    <fixed name="mimic_rev_motor_08_2">
      <joint joint="rev_motor_08_2" coef="1"/>
      <joint joint="rev_motor_08" coef="-0.0115"/>
    </fixed>
  </tendon>
  <actuator>
    <position name="act_motor_01" joint="rev_motor_01" kp="15.0" kv="0.5" ctrlrange="-1.5509 1.5509" forcerange="-2.94 2.94"/>
    <position name="act_motor_02" joint="rev_motor_02" kp="15.0" kv="0.5" ctrlrange="-1.6122 1.6122" forcerange="-2.94 2.94"/>
    <position name="act_motor_03" joint="rev_motor_03" kp="15.0" kv="0.5" ctrlrange="-1.761 1.761" forcerange="-2.94 2.94"/>
    <position name="act_motor_04" joint="rev_motor_04" kp="15.0" kv="0.5" ctrlrange="-1.7533 1.7533" forcerange="-2.94 2.94"/>
    <position name="act_motor_05" joint="rev_motor_05" kp="15.0" kv="0.5" ctrlrange="-3.1907 2.6998" forcerange="-2.94 2.94"/>
    <position name="act_motor_06" joint="rev_motor_06" kp="15.0" kv="0.5" ctrlrange="-1.3775 1.7641" forcerange="-2.94 2.94"/>
    <position name="act_motor_07" joint="rev_motor_07" kp="15.0" kv="0.5" ctrlrange="-3.071 2.7796" forcerange="-2.94 2.94"/>
    <position name="act_motor_08" joint="rev_motor_08" kp="10.0" kv="0.3" ctrlrange="0.0 2.2028" forcerange="-2.94 2.94"/>
  </actuator>
  <default>
    <default class="arm_link">
      <geom contype="1" conaffinity="1" friction="0.9 0.005 0.0001"/>
    </default>
    <default class="gripper_finger">
      <geom contype="2" conaffinity="3" friction="1.5 0.05 0.001"/>
    </default>
  </default>
</mujoco>
